<?xml version="1.0"?>
<robot  xmlns:xacro="http://www.ros.org/wiki/xacro" name="rrbot">

 <xacro:include filename="$(find robot_sim)/urdf/materials.xacro" />
 <link name="dummy">
   </link>
<link name="base_link">
    <inertial>
      <origin
        xyz="0.15 0.15 .2"
        rpy="0 0 0" />
      <mass
        value="10" />
      <inertia
        ixx="0"
        ixy="0"
        ixz="0"
        iyy="0"
        iyz="0"
        izz="0" />
    </inertial>
    <visual>
      <origin
        xyz="0 0 0"
        rpy="0 0 0" />
      <geometry>
        <mesh
          filename="package://robot_sim/meshes/base_link.STL" />
      </geometry>
      <material
        name="">
        <color
          rgba="0.792156862745098 0.819607843137255 0.933333333333333 1" />
      </material>
    </visual>
    <collision>
      <origin
        xyz="0 0 0"
        rpy="0 0 0" />
      <geometry>
        <mesh
          filename="package://robot_sim/meshes/base_link.STL" />
      </geometry>
    </collision>
  </link>
  <joint name="dummy_joint" type="fixed">
     <parent link="dummy"/>
     <child link="base_link"/>
   </joint>
<link
    name="L1">
    <inertial>
      <origin
        xyz="0.14 0.00999999999999998 0.0647872340425532"
        rpy="0 0 0" />
      <mass
        value="0.188" />
      <inertia
        ixx="0"
        ixy="0"
        ixz="0"
        iyy="0"
        iyz="0"
        izz="0" />
    </inertial>
    <visual>
      <origin
        xyz="0 0 0"
        rpy="0 0 0" />
      <geometry>
        <mesh
          filename="package://robot_sim/meshes/L1.STL" />
      </geometry>
      <material
        name="">
        <color
          rgba="0.792156862745098 0.819607843137255 0.933333333333333 1" />
      </material>
    </visual>
    <collision>
      <origin
        xyz="0 0 0"
        rpy="0 0 0" />
      <geometry>
        <mesh
          filename="package://robot_sim/meshes/L1.STL" />
      </geometry>
    </collision>
  </link>

<joint name="J1" type="prismatic">
   <parent link="base_link"/>
   <child link="L1"/>
   <limit effort="1000.0" lower="-100" upper="100" velocity="0.5"/>
   <origin rpy="0 0 0" xyz="0.01 0.197440112838672 0.2"/>
   <axis
     xyz="0 1 0" />
 </joint>


<link name="L2">
    <inertial>
      <origin
        xyz="0.015 0.0014799004971911 0.00165487689757998"
        rpy="0 0 0" />
      <mass
        value="0.00887444678594554" />
      <inertia
        ixx="0"
        ixy="0"
        ixz="0"
        iyy="0"
        iyz="0"
        izz="0" />
    </inertial>
    <visual>
      <origin
        xyz="0 0 0"
        rpy="0 0 0" />
      <geometry>
        <mesh
          filename="package://robot_sim/meshes/L2.STL" />
      </geometry>
      <material
        name="">
        <color
          rgba="0.792156862745098 0.819607843137255 0.933333333333333 1" />
      </material>
    </visual>
    <collision>
      <origin
        xyz="0 0 0"
        rpy="0 0 0" />
      <geometry>
        <mesh
          filename="package://robot_sim/meshes/L2.STL" />
      </geometry>
    </collision>
  </link>

 <joint name="J2" type="prismatic">
    <parent link="L1"/>
    <child link="L2"/>
    <limit effort="1000.0" lower="0" upper=".2" velocity="0.5"/>
    <origin rpy="0 0 0" xyz=".1 0.0 .09"/>

  </joint>
  <link  name="L3">
      <inertial>
        <origin
         xyz="0.0 0.0 0"
          rpy="0 0 0" />
        <mass
          value="0.0117809724509617" />
        <inertia
          ixx="0"
          ixy="0"
          ixz="0"
          iyy="0"
          iyz="0"
          izz="0" />
      </inertial>
      <collision>
        <origin
          xyz="0 0 0"
          rpy="0 0 0" />
        <geometry>
          <mesh
            filename="package://robot_sim/meshes/L3.STL" />
        </geometry>
      </collision>
      <visual>
        <origin
          xyz="0.0 -0.0 0"
          rpy="0 0 0" />
        <geometry>
          <mesh
            filename="package://robot_sim/meshes/L3.STL" />
        </geometry>
        <material
          name="">
          <color
            rgba="0.792156862745098 0.819607843137255 0.933333333333333 1" />
        </material>
      </visual>

    </link>

<link name="niddle">

<inertial>
  <mass value="0.001" />
  <origin xyz="0 0 0" rpy="0 0 0"/>
  <inertia ixx="0" ixy="0" ixz="0" iyy="0" iyz="0" izz="0" />
</inertial>
    <collision name="collision">
     <geometry>
     <cylinder length="0.01" radius="0.001"/>
     </geometry>
</collision>
   <visual name="visual">
     <geometry>
     <cylinder length="0.01" radius="0.001"/>
     </geometry>
   </visual>
 </link>

<link name="camera_link">
      <visual>
        <origin xyz="0 0 0" rpy="0 0 0"/>
        <geometry>
      <box size="0.01 0.01 0.01"/>
        </geometry>
        <material name="orange"/>
      </visual>

      <inertial>
        <mass value="1e-5" />
        <origin xyz="0 0 0" rpy="0 0 0"/>
        <inertia ixx="1e-6" ixy="0" ixz="0" iyy="1e-6" iyz="0" izz="1e-6" />
      </inertial>
    </link>

   <joint name="J3" type="prismatic">
      <parent link="L2"/>
      <child link="L3"/>
      <limit effort="1000.0" lower="0" upper="0.09" velocity="0.5"/>
      <origin rpy="0 0 0" xyz="0.015 -0.0150 0"/>
      <axis xyz="0 0 -1" />
    </joint>



<joint name="J4" type="continuous">
 <parent link="L2"/>
 <child link="camera_link"/>
 <origin rpy="0 0 0" xyz="0.015  -0.035 0"/>
</joint>

<joint name="J5" type="continuous">
   <parent link="L3"/>
   <child link="niddle"/>
    <origin rpy="0 0 0" xyz="0.00 -0.00 -0.005"/>
   <axis xyz="0 0 1" />
 </joint>

<transmission name="tran1">
    <type>transmission_interface/SimpleTransmission</type>
    <joint name="J1">
      <hardwareInterface>hardware_interface/EffortJointInterface</hardwareInterface>
    </joint>
    <actuator name="motor1">
      <hardwareInterface>hardware_interface/EffortJointInterface</hardwareInterface>
      <mechanicalReduction>1</mechanicalReduction>
    </actuator>
  </transmission>

 <transmission name="tran2">
     <type>transmission_interface/SimpleTransmission</type>
     <joint name="J2">
       <hardwareInterface>hardware_interface/EffortJointInterface</hardwareInterface>
     </joint>
     <actuator name="motor2">
       <hardwareInterface>hardware_interface/EffortJointInterface</hardwareInterface>
       <mechanicalReduction>1</mechanicalReduction>
     </actuator>
   </transmission>

<transmission name="tran3">
    <type>transmission_interface/SimpleTransmission</type>
    <joint name="J3">
      <hardwareInterface>hardware_interface/EffortJointInterface</hardwareInterface>
    </joint>
    <actuator name="motor3">
      <hardwareInterface>hardware_interface/EffortJointInterface</hardwareInterface>
      <mechanicalReduction>1</mechanicalReduction>
    </actuator>
  </transmission>

<transmission name="tran4">
    <type>transmission_interface/SimpleTransmission</type>
    <joint name="J5">
      <hardwareInterface>hardware_interface/EffortJointInterface</hardwareInterface>
    </joint>
    <actuator name="motor4">
      <hardwareInterface>hardware_interface/EffortJointInterface</hardwareInterface>
      <mechanicalReduction>1</mechanicalReduction>
    </actuator>
  </transmission>


  <!-- Gazebo plugin for ROS Control -->
  <gazebo>
    <plugin name="gazebo_ros_control" filename="libgazebo_ros_control.so">
      <robotNamespace>/rrbot</robotNamespace>
    </plugin>
</gazebo>




<gazebo reference="L3">
  <sensor type="camera" name="camera1">
    <update_rate>30.0</update_rate>
    <camera name="head">
      <horizontal_fov>1.3962634</horizontal_fov>
      <image>
        <width>800</width>
        <height>800</height>
        <format>R8G8B8</format>
      </image>
      <clip>
        <near>0.02</near>
        <far>300</far>
      </clip>
      <noise>
        <type>gaussian</type>
        <!-- Noise is sampled independently per pixel on each frame.
             That pixel's noise value is added to each of its color
             channels, which at that point lie in the range [0,1]. -->
        <mean>0.0</mean>
        <stddev>0.007</stddev>
      </noise>
    </camera>
    <plugin name="camera_controller" filename="libgazebo_ros_camera.so">
      <alwaysOn>true</alwaysOn>
      <updateRate>0.0</updateRate>
      <cameraName>rrbot/camera1</cameraName>
      <imageTopicName>image_raw</imageTopicName>
      <cameraInfoTopicName>camera_info</cameraInfoTopicName>
      <frameName>camera_link</frameName>
      <hackBaseline>0.07</hackBaseline>
      <distortionK1>0.0</distortionK1>
      <distortionK2>0.0</distortionK2>
      <distortionK3>0.0</distortionK3>
      <distortionT1>0.0</distortionT1>
      <distortionT2>0.0</distortionT2>
    </plugin>
  </sensor>
</gazebo>

<gazebo reference="L3">
    <material>Gazebo/Orange</material>
</gazebo>
<gazebo reference="niddle">
    <material>Gazebo/Orange</material>
</gazebo>
  </robot>
