<?xml version="1.0"?>

<robot  xmlns:xacro="http://www.ros.org/wiki/xacro" name="rrbot">


<link
    name="base_link">
    <inertial>
      <origin
        xyz="0.249025149842267 0.288536369831321 0.424095630505477"
        rpy="0 0 0" />
      <mass
        value="1200.2" />
      <inertia
        ixx="0"
        ixy="0"
        ixz="0"
        iyy="0"
        iyz="0"
        izz="0" />
    </inertial>
    <visual>
      <origin
        xyz="0 0 0"
        rpy="0 0 0" />
      <geometry>
        <mesh
          filename="package://robot_sim/meshes/base_link.STL" />
      </geometry>
      <material
        name="">
        <color
          rgba="0.792156862745098 0.819607843137255 0.933333333333333 1" />
      </material>
    </visual>
    <collision>
      <origin
        xyz="0 0 0"
        rpy="0 0 0" />
      <geometry>
        <mesh
          filename="package://robot_sim/meshes/base_link.STL" />
      </geometry>
    </collision>
  </link>

<link
    name="p1">
    <inertial>
      <origin
        xyz="1.38777878078145E-16 0.185555555555556 0.0200000000000001"
        rpy="0 0 0" />
      <mass
        value="1.512" />
      <inertia
        ixx="0"
        ixy="0"
        ixz="0"
        iyy="0"
        iyz="0"
        izz="0" />
    </inertial>
    <visual>
      <origin
        xyz="0 0 0"
        rpy="0 0 0" />
      <geometry>
        <mesh
          filename="package://robot_sim/meshes/p1.STL" />
      </geometry>
      <material
        name="">
        <color
          rgba="0.792156862745098 0.819607843137255 0.933333333333333 1" />
      </material>
    </visual>
    <collision>
      <origin
        xyz="0 0 0"
        rpy="0 0 0" />
      <geometry>
        <mesh
          filename="package://robot_sim/meshes/p1.STL" />
      </geometry>
    </collision>
  </link>

<joint  name="j1"   type="prismatic">

    <origin
      xyz="0.249025149842267 0.1 0.50"
      rpy="0 0 0" />
    <parent
      link="base_link" />
    <child
      link="p1" />
    <axis
      xyz="0 1 0" />
      <limit effort="1000.0" lower="-0.05" upper=".4" velocity="0.5"/>
  </joint>

<link    name="p2">
    <inertial>
      <origin
        xyz="-0.02 0.03 0.052047787481715"
        rpy="0 0 0" />
      <mass
        value="0.122547568872596" />
      <inertia
        ixx="0"
        ixy="0"
        ixz="0"
        iyy="0"
        iyz="0"
        izz="0" />
    </inertial>
    <visual>
      <origin
        xyz="0 0 0"
        rpy="0 0 0" />
      <geometry>
        <mesh
          filename="package://robot_sim/meshes/p2.STL" />
      </geometry>
      <material
        name="">
        <color
          rgba="0.792156862745098 0.819607843137255 0.933333333333333 1" />
      </material>
    </visual>
    <collision>
      <origin
        xyz="0 0 0"
        rpy="0 0 0" />
      <geometry>
        <mesh
          filename="package://robot_sim/meshes/p2.STL" />
      </geometry>
    </collision>
  </link>

<joint    name="j2"    type="prismatic">
    <origin
      xyz="-0.0 -0.04 0.21"
      rpy="0 0 3.1415" />
    <parent
      link="p1" />
    <child
      link="p2" />
    <axis
      xyz="1 0 0" />
      <limit effort="1000.0" lower="-0.23" upper="0.27" velocity="0.5"/>
  </joint>
<!--bolbring -->
<link    name="p3">
    <inertial>
      <origin
        xyz="0 -0.0310687231692988 0.000105308099467155"
        rpy="0 0 0" />
      <mass
        value="0.161431077818511" />
      <inertia
        ixx="0"
        ixy="0"
        ixz="0"
        iyy="0"
        iyz="0"
        izz="0" />
    </inertial>
    <visual>
      <origin
        xyz="0.04 0 0"
        rpy="0 0 1.57" />
      <geometry>
        <mesh
          filename="package://robot_sim/meshes/p3.STL" />
      </geometry>
      <material
        name="">
        <color
          rgba="0.792156862745098 0.819607843137255 0.933333333333333 1" />
      </material>
    </visual>
    <collision>
      <origin
        xyz="0 0 0"
        rpy="0 0 0" />
      <geometry>
        <mesh
          filename="package://robot_sim/meshes/p3.STL" />
      </geometry>
    </collision>
  </link>
<!--bolbring end -->
<joint name="j3"   type="continuous">
    <origin
      xyz="-0.02 -0.07 0.04"
      rpy="0 1.57 0" />
    <parent
      link="p2" />
    <child
      link="p3" />
    <axis
      xyz="1 0 0" />
  </joint>

<link   name="p4">
    <inertial>
      <origin
        xyz="0.0137795085596931 -0.002 0.00800000000000012"
        rpy="0 0 0" />
      <mass
        value="2" />
      <inertia
        ixx="0"
        ixy="0"
        ixz="0"
        iyy="0"
        iyz="0"
        izz="0" />
    </inertial>
    <visual>
      <origin
        xyz="0 0 0"
        rpy="0 0 0" />
      <geometry>
        <mesh
          filename="package://robot_sim/meshes/p4.STL" />
      </geometry>
      <material
        name="">
        <color
          rgba="0.792156862745098 0.819607843137255 0.933333333333333 1" />
      </material>
    </visual>
    <collision>
      <origin
        xyz="0 0 0"
        rpy="0 0 0" />
      <geometry>
        <mesh
          filename="package://robot_sim/meshes/p4.STL" />
      </geometry>
    </collision>
  </link>

<joint    name="j4"    type="prismatic">
    <origin
      xyz="0 0 0"
      rpy="0 0 1.57" />
    <parent
      link="p3" />
    <child
      link="p4" />
    <axis
      xyz="0 1 0" />
      <limit effort="1000.0" lower="-0.073" upper="-0.010" velocity="0.5"/>
  </joint>

<link   name="p5">
    <inertial>
      <origin
        xyz="0.0137795085596931 -0.002 0.00800000000000012"
        rpy="0 0 0" />
      <mass
        value="1" />
      <inertia
        ixx="0"
        ixy="0"
        ixz="0"
        iyy="0"
        iyz="0"
        izz="0" />
    </inertial>
    <visual>
      <origin
        xyz="0 0 0"
        rpy="0 0 0" />
      <geometry>
        <mesh
          filename="package://robot_sim/meshes/p5.STL" />
      </geometry>
      <material
        name="">
        <color
          rgba="0.792156862745098 0.819607843137255 0.933333333333333 1" />
      </material>
    </visual>
    <collision>
      <origin
        xyz="0 0 0"
        rpy="0 0 0" />
      <geometry>
        <mesh
          filename="package://robot_sim/meshes/p5.STL" />
      </geometry>
    </collision>
  </link>

<joint    name="j5"    type="prismatic">
    <origin
      xyz="-0.0085 -0.1332 0"
      rpy="0 1.57 0" />
    <parent
      link="p4" />
    <child
      link="p5" />
    <axis
      xyz="1 0 0" />
      <limit effort="1000.0" lower="-0.1" upper="0.02" velocity="0.5"/>
  </joint>

<transmission name="tran1">
    <type>transmission_interface/SimpleTransmission</type>
    <joint name="j1">
      <hardwareInterface>hardware_interface/EffortJointInterface</hardwareInterface>
    </joint>
    <actuator name="motor1">
      <hardwareInterface>hardware_interface/EffortJointInterface</hardwareInterface>
      <mechanicalReduction>1</mechanicalReduction>
    </actuator>
  </transmission>

 <transmission name="tran2">
     <type>transmission_interface/SimpleTransmission</type>
     <joint name="j2">
       <hardwareInterface>hardware_interface/EffortJointInterface</hardwareInterface>
     </joint>
     <actuator name="motor2">
       <hardwareInterface>hardware_interface/EffortJointInterface</hardwareInterface>
       <mechanicalReduction>1</mechanicalReduction>
     </actuator>
   </transmission>

<transmission name="tran3">
    <type>transmission_interface/SimpleTransmission</type>
    <joint name="j3">
      <hardwareInterface>hardware_interface/EffortJointInterface</hardwareInterface>
    </joint>
    <actuator name="motor3">
      <hardwareInterface>hardware_interface/EffortJointInterface</hardwareInterface>
      <mechanicalReduction>1</mechanicalReduction>
    </actuator>
  </transmission>

<transmission name="tran4">
    <type>transmission_interface/SimpleTransmission</type>
    <joint name="j4">
      <hardwareInterface>hardware_interface/EffortJointInterface</hardwareInterface>
    </joint>
    <actuator name="motor4">
      <hardwareInterface>hardware_interface/EffortJointInterface</hardwareInterface>
      <mechanicalReduction>1</mechanicalReduction>
    </actuator>
  </transmission>

<transmission name="tran5">
      <type>transmission_interface/SimpleTransmission</type>
      <joint name="j5">
        <hardwareInterface>hardware_interface/EffortJointInterface</hardwareInterface>
      </joint>
      <actuator name="motor5">
        <hardwareInterface>hardware_interface/EffortJointInterface</hardwareInterface>
        <mechanicalReduction>1</mechanicalReduction>
      </actuator>
    </transmission>



  <!-- Gazebo plugin for ROS Control -->
  <gazebo>
    <plugin name="gazebo_ros_control" filename="libgazebo_ros_control.so">
      <robotNamespace>/rrbot</robotNamespace>
    </plugin>
</gazebo>

<gazebo reference="p1">
    <material>Gazebo/Orange</material>
</gazebo>
<gazebo reference="p2">
    <material>Gazebo/Blue</material>
</gazebo>
<gazebo reference="p3">
    <material>Gazebo/Yellow</material>
</gazebo>
<gazebo reference="p4">
    <material>Gazebo/Purple</material>
</gazebo>
<gazebo reference="p5">
    <material>Gazebo/Red</material>
</gazebo>
</robot>
