<?xml version="1.0"?>

<robot  xmlns:xacro="http://www.ros.org/wiki/xacro" name="rrbot">


<link name="base_link">
    <inertial>
      <origin
        xyz="0.249025149842267 0.288536369831321 0.424095630505477"
        rpy="0 0 0" />
      <mass
        value="1200.2" />
      <inertia
        ixx="0"
        ixy="0"
        ixz="0"
        iyy="0"
        iyz="0"
        izz="0" />
    </inertial>
    <visual>
      <origin
        xyz="0 0 0"
        rpy="0 0 0" />
      <geometry>
        <mesh
          filename="package://robot_sim/meshes/base_link.STL" />
      </geometry>
      <material
        name="">
        <color
          rgba="0.792156862745098 0.819607843137255 0.933333333333333 1" />
      </material>
    </visual>
    <collision>
      <origin
        xyz="0 0 0"
        rpy="0 0 0" />
      <geometry>
        <mesh
          filename="package://robot_sim/meshes/base_link.STL" />
      </geometry>
    </collision>
  </link>

<link
    name="p1">
    <inertial>
      <origin
        xyz="1.38777878078145E-16 0.185555555555556 0.0200000000000001"
        rpy="0 0 0" />
      <mass
        value="1.512" />
      <inertia
        ixx="0"
        ixy="0"
        ixz="0"
        iyy="0"
        iyz="0"
        izz="0" />
    </inertial>
    <visual>
      <origin
        xyz="0 0 0"
        rpy="0 0 0" />
      <geometry>
        <mesh
          filename="package://robot_sim/meshes/p1.STL" />
      </geometry>
      <material
        name="">
        <color
          rgba="0.792156862745098 0.819607843137255 0.933333333333333 1" />
      </material>
    </visual>
    <collision>
      <origin
        xyz="0 0 0"
        rpy="0 0 0" />
      <geometry>
        <mesh
          filename="package://robot_sim/meshes/p1.STL" />
      </geometry>
    </collision>
  </link>

<joint  name="j1"   type="prismatic">

    <origin
      xyz="0.249025149842267 0.1 0.50"
      rpy="0 0 0" />
    <parent
      link="base_link" />
    <child
      link="p1" />
    <axis
      xyz="0 1 0" />
      <limit effort="1000.0" lower="-0.05" upper=".4" velocity="0.5"/>
  </joint>

<link    name="p2">
    <inertial>
      <origin
        xyz="-0.02 0.03 0.052047787481715"
        rpy="0 0 0" />
      <mass
        value="0.122547568872596" />
      <inertia
        ixx="0"
        ixy="0"
        ixz="0"
        iyy="0"
        iyz="0"
        izz="0" />
    </inertial>
    <visual>
      <origin
        xyz="0 0 0"
        rpy="0 0 0" />
      <geometry>
        <mesh
          filename="package://robot_sim/meshes/p2.STL" />
      </geometry>
      <material
        name="">
        <color
          rgba="0.792156862745098 0.819607843137255 0.933333333333333 1" />
      </material>
    </visual>
    <collision>
      <origin
        xyz="0 0 0"
        rpy="0 0 0" />
      <geometry>
        <mesh
          filename="package://robot_sim/meshes/p2.STL" />
      </geometry>
    </collision>
  </link>

<link name="camera_link">
      <visual>
        <origin xyz="0 0 0" rpy="0 0 0"/>
        <geometry>
      <box size="0.01 0.01 0.01"/>
        </geometry>
        <material name="orange"/>
      </visual>

      <inertial>
        <mass value="1e-5" />
        <origin xyz="0 0 0" rpy="0 0 0"/>
        <inertia ixx="1e-6" ixy="0" ixz="0" iyy="1e-6" iyz="0" izz="1e-6" />
      </inertial>
</link>

<joint    name="j2"    type="prismatic">
    <origin
      xyz="-0.0 -0.04 0.21"
      rpy="0 0 3.1415" />
    <parent
      link="p1" />
    <child
      link="p2" />
    <axis
      xyz="1 0 0" />
      <limit effort="1000.0" lower="-0.23" upper="0.27" velocity="0.5"/>
  </joint>

<joint name="camare_joints" type="prismatic">
   <parent link="p2"/>
   <child link="camera_link"/>
   <limit effort="1000.0" lower="0.0" upper="0.0001" velocity="0.5"/>
   <origin rpy="0 1.57 0" xyz="-0.02 -0.095 0"/>
   <axis xyz="0 0 -1" />
</joint>

<!--bolbring -->
<link    name="p3">
    <inertial>
      <origin
        xyz="0 -0.0310687231692988 0.000105308099467155"
        rpy="0 0 0" />
      <mass
        value="0.161431077818511" />
      <inertia
        ixx="0"
        ixy="0"
        ixz="0"
        iyy="0"
        iyz="0"
        izz="0" />
    </inertial>
    <visual>
      <origin
        xyz="0.04 0 0"
        rpy="0 0 1.57" />
      <geometry>
        <mesh
          filename="package://robot_sim/meshes/p3.STL" />
      </geometry>
      <material
        name="">
        <color
          rgba="0.792156862745098 0.819607843137255 0.933333333333333 1" />
      </material>
    </visual>
    <collision>
      <origin
        xyz="0 0 0"
        rpy="0 0 0" />
      <geometry>
        <mesh
          filename="package://robot_sim/meshes/p3.STL" />
      </geometry>
    </collision>
  </link>

<!--bolbring end -->
<joint name="j3"   type="continuous">
    <origin
      xyz="-0.02 -0.07 0.04"
      rpy="0 1.57 0" />
    <parent
      link="p2" />
    <child
      link="p3" />
    <axis
      xyz="1 0 0" />
  </joint>

<link   name="p4">
    <inertial>
      <origin
        xyz="0.0137795085596931 -0.002 0.00800000000000012"
        rpy="0 0 0" />
      <mass
        value="2" />
      <inertia
        ixx="0"
        ixy="0"
        ixz="0"
        iyy="0"
        iyz="0"
        izz="0" />
    </inertial>
    <visual>
      <origin
        xyz="0 0 0"
        rpy="0 0 0" />
      <geometry>
        <mesh
          filename="package://robot_sim/meshes/p4.STL" />
      </geometry>
      <material
        name="">
        <color
          rgba="0.792156862745098 0.819607843137255 0.933333333333333 1" />
      </material>
    </visual>
    <collision>
      <origin
        xyz="0 0 0"
        rpy="0 0 0" />
      <geometry>
        <mesh
          filename="package://robot_sim/meshes/p4.STL" />
      </geometry>
    </collision>
  </link>

<joint    name="j4"    type="prismatic">
    <origin
      xyz="0 0 0"
      rpy="0 0 1.57" />
    <parent
      link="p3" />
    <child
      link="p4" />
    <axis
      xyz="0 -1 0" />
      <limit effort="1000.0" lower="-0.006" upper="0.066" velocity="0.5"/>
  </joint>

<link   name="p5">
    <inertial>
      <origin
        xyz="0.0137795085596931 -0.002 0.00800000000000012"
        rpy="0 0 0" />
      <mass
        value="1" />
      <inertia
        ixx="0"
        ixy="0"
        ixz="0"
        iyy="0"
        iyz="0"
        izz="0" />
    </inertial>
    <visual>
      <origin
        xyz="0 0 0"
        rpy="0 0 0" />
      <geometry>
        <mesh
          filename="package://robot_sim/meshes/p5.STL" />
      </geometry>
      <material
        name="">
        <color
          rgba="0.792156862745098 0.819607843137255 0.933333333333333 1" />
      </material>
    </visual>
    <collision>
      <origin
        xyz="0 0 0"
        rpy="0 0 0" />
      <geometry>
        <mesh
          filename="package://robot_sim/meshes/p5.STL" />
      </geometry>
    </collision>
  </link>

<joint    name="j5"    type="prismatic">
    <origin
      xyz="-0.0085 -0.1332 0"
      rpy="0 1.57 0" />
    <parent
      link="p4" />
    <child
      link="p5" />
    <axis
      xyz="-1 0 0" />
      <limit effort="10.0" lower="-0.02" upper="0.01" velocity="0.5"/>
  </joint>

<transmission name="tran1">
    <type>transmission_interface/SimpleTransmission</type>
    <joint name="j1">
      <hardwareInterface>hardware_interface/EffortJointInterface</hardwareInterface>
    </joint>
    <actuator name="motor1">
      <hardwareInterface>hardware_interface/EffortJointInterface</hardwareInterface>
      <mechanicalReduction>1</mechanicalReduction>
    </actuator>
  </transmission>

 <transmission name="tran2">
     <type>transmission_interface/SimpleTransmission</type>
     <joint name="j2">
       <hardwareInterface>hardware_interface/EffortJointInterface</hardwareInterface>
     </joint>
     <actuator name="motor2">
       <hardwareInterface>hardware_interface/EffortJointInterface</hardwareInterface>
       <mechanicalReduction>1</mechanicalReduction>
     </actuator>
   </transmission>

<transmission name="tran3">
    <type>transmission_interface/SimpleTransmission</type>
    <joint name="j3">
      <hardwareInterface>hardware_interface/EffortJointInterface</hardwareInterface>
    </joint>
    <actuator name="motor3">
      <hardwareInterface>hardware_interface/EffortJointInterface</hardwareInterface>
      <mechanicalReduction>1</mechanicalReduction>
    </actuator>
  </transmission>

<transmission name="tran4">
    <type>transmission_interface/SimpleTransmission</type>
    <joint name="j4">
      <hardwareInterface>hardware_interface/EffortJointInterface</hardwareInterface>
    </joint>
    <actuator name="motor4">
      <hardwareInterface>hardware_interface/EffortJointInterface</hardwareInterface>
      <mechanicalReduction>1</mechanicalReduction>
    </actuator>
  </transmission>

<transmission name="tran5">
      <type>transmission_interface/SimpleTransmission</type>
      <joint name="j5">
        <hardwareInterface>hardware_interface/EffortJointInterface</hardwareInterface>
      </joint>
      <actuator name="motor5">
        <hardwareInterface>hardware_interface/EffortJointInterface</hardwareInterface>
        <mechanicalReduction>1</mechanicalReduction>
      </actuator>
    </transmission>



  <!-- Gazebo plugin for ROS Control -->
  <gazebo>
    <plugin name="gazebo_ros_control" filename="libgazebo_ros_control.so">
      <robotNamespace>/rrbot</robotNamespace>
    </plugin>
</gazebo>

<gazebo reference="camera_link">
  <sensor type="camera" name="camera1">
    <update_rate>30.0</update_rate>
    <camera name="head">
      <horizontal_fov>1.3962634</horizontal_fov>
      <image>
        <width>800</width>
        <height>800</height>
        <format>R8G8B8</format>
      </image>
      <clip>
        <near>0.02</near>
        <far>300</far>
      </clip>
      <noise>
        <type>gaussian</type>
        <!-- Noise is sampled independently per pixel on each frame.
             That pixel's noise value is added to each of its color
             channels, which at that point lie in the range [0,1]. -->
        <mean>0.0</mean>
        <stddev>0.007</stddev>
      </noise>
    </camera>
    <plugin name="camera_controller" filename="libgazebo_ros_camera.so">
      <alwaysOn>true</alwaysOn>
      <updateRate>0.0</updateRate>
      <cameraName>rrbot/camera1</cameraName>
      <imageTopicName>image_raw</imageTopicName>
      <cameraInfoTopicName>camera_info</cameraInfoTopicName>
      <frameName>camera_link</frameName>
      <hackBaseline>0.07</hackBaseline>
      <distortionK1>0.0</distortionK1>
      <distortionK2>0.0</distortionK2>
      <distortionK3>0.0</distortionK3>
      <distortionT1>0.0</distortionT1>
      <distortionT2>0.0</distortionT2>
    </plugin>
  </sensor>
</gazebo>

<gazebo reference="base_link">
<collision name="base_link_collision">
<surface>
  <friction>
    <ode>
      <mu>1.0</mu>
      <mu2>1.0</mu2>
      <fdir1>0 0 0</fdir1>
      <slip1>0</slip1>
      <slip2>0</slip2>
    </ode>
    <torsional>
      <coefficient>1</coefficient>
      <patch_radius>0</patch_radius>
      <surface_radius>0</surface_radius>
      <use_patch_radius>1</use_patch_radius>
      <ode>
        <slip>0</slip>
      </ode>
    </torsional>
  </friction>
  <bounce>
    <restitution_coefficient>0</restitution_coefficient>
    <threshold>1e+06</threshold>
  </bounce>
  <contact>
    <collide_without_contact>0</collide_without_contact>
    <collide_without_contact_bitmask>1</collide_without_contact_bitmask>
    <collide_bitmask>1</collide_bitmask>
    <ode>
      <soft_cfm>0</soft_cfm>
      <soft_erp>0.2</soft_erp>
      <kp>1e+10</kp>
      <kd>1</kd>
      <max_vel>0.1</max_vel>
      <min_depth>0.001</min_depth>
    </ode>
    <bullet>
      <split_impulse>1</split_impulse>
      <split_impulse_penetration_threshold>-0.01</split_impulse_penetration_threshold>
      <soft_cfm>0</soft_cfm>
      <soft_erp>0.2</soft_erp>
      <kp>1e+7</kp>
      <kd>1.0</kd>
    </bullet>
  </contact>
</surface>
   </collision>
    <material>Gazebo/White</material>

</gazebo>

<gazebo reference="p1">
<collision name="p1_collision">
<surface>
  <friction>
    <ode>
      <mu>1.0</mu>
      <mu2>1.0</mu2>
      <fdir1>0 0 0</fdir1>
      <slip1>0</slip1>
      <slip2>0</slip2>
    </ode>
    <torsional>
      <coefficient>1</coefficient>
      <patch_radius>0</patch_radius>
      <surface_radius>0</surface_radius>
      <use_patch_radius>1</use_patch_radius>
      <ode>
        <slip>0</slip>
      </ode>
    </torsional>
  </friction>
  <bounce>
    <restitution_coefficient>0</restitution_coefficient>
    <threshold>1e+06</threshold>
  </bounce>
  <contact>
    <collide_without_contact>0</collide_without_contact>
    <collide_without_contact_bitmask>1</collide_without_contact_bitmask>
    <collide_bitmask>1</collide_bitmask>
    <ode>
      <soft_cfm>0</soft_cfm>
      <soft_erp>0.2</soft_erp>
      <kp>1e+10</kp>
      <kd>1</kd>
      <max_vel>0.1</max_vel>
      <min_depth>0.001</min_depth>
    </ode>
    <bullet>
      <split_impulse>1</split_impulse>
      <split_impulse_penetration_threshold>-0.01</split_impulse_penetration_threshold>
      <soft_cfm>0</soft_cfm>
      <soft_erp>0.2</soft_erp>
      <kp>1e+7</kp>
      <kd>1.0</kd>
    </bullet>
  </contact>
</surface>
   </collision>
    <material>Gazebo/Orange</material>
</gazebo>
<gazebo reference="p2">
<collision name="p2_collision">
<surface>
  <friction>
    <ode>
      <mu>1.0</mu>
      <mu2>1.0</mu2>
      <fdir1>0 0 0</fdir1>
      <slip1>0</slip1>
      <slip2>0</slip2>
    </ode>
    <torsional>
      <coefficient>1</coefficient>
      <patch_radius>0</patch_radius>
      <surface_radius>0</surface_radius>
      <use_patch_radius>1</use_patch_radius>
      <ode>
        <slip>0</slip>
      </ode>
    </torsional>
  </friction>
  <bounce>
    <restitution_coefficient>0</restitution_coefficient>
    <threshold>1e+06</threshold>
  </bounce>
  <contact>
    <collide_without_contact>0</collide_without_contact>
    <collide_without_contact_bitmask>1</collide_without_contact_bitmask>
    <collide_bitmask>1</collide_bitmask>
    <ode>
      <soft_cfm>0</soft_cfm>
      <soft_erp>0.2</soft_erp>
      <kp>1e+10</kp>
      <kd>1</kd>
      <max_vel>0.1</max_vel>
      <min_depth>0.001</min_depth>
    </ode>
    <bullet>
      <split_impulse>1</split_impulse>
      <split_impulse_penetration_threshold>-0.01</split_impulse_penetration_threshold>
      <soft_cfm>0</soft_cfm>
      <soft_erp>0.2</soft_erp>
      <kp>1e+7</kp>
      <kd>1.0</kd>
    </bullet>
  </contact>
</surface>
   </collision>
    <material>Gazebo/Blue</material>
</gazebo>
<gazebo reference="p3">
<collision name="p3_collision">
<surface>
  <friction>
    <ode>
      <mu>1.0</mu>
      <mu2>1.0</mu2>
      <fdir1>0 0 0</fdir1>
      <slip1>0</slip1>
      <slip2>0</slip2>
    </ode>
    <torsional>
      <coefficient>1</coefficient>
      <patch_radius>0</patch_radius>
      <surface_radius>0</surface_radius>
      <use_patch_radius>1</use_patch_radius>
      <ode>
        <slip>0</slip>
      </ode>
    </torsional>
  </friction>
  <bounce>
    <restitution_coefficient>0</restitution_coefficient>
    <threshold>1e+06</threshold>
  </bounce>
  <contact>
    <collide_without_contact>0</collide_without_contact>
    <collide_without_contact_bitmask>1</collide_without_contact_bitmask>
    <collide_bitmask>1</collide_bitmask>
    <ode>
      <soft_cfm>0</soft_cfm>
      <soft_erp>0.2</soft_erp>
      <kp>1e+10</kp>
      <kd>1</kd>
      <max_vel>0.1</max_vel>
      <min_depth>0.001</min_depth>
    </ode>
    <bullet>
      <split_impulse>1</split_impulse>
      <split_impulse_penetration_threshold>-0.01</split_impulse_penetration_threshold>
      <soft_cfm>0</soft_cfm>
      <soft_erp>0.2</soft_erp>
      <kp>1e+7</kp>
      <kd>1.0</kd>
    </bullet>
  </contact>
</surface>
   </collision>
    <material>Gazebo/Yellow</material>
</gazebo>
<gazebo reference="p4">
<collision name="p4_collision">
<surface>
  <friction>
    <ode>
      <mu>1.0</mu>
      <mu2>1.0</mu2>
      <fdir1>0 0 0</fdir1>
      <slip1>0</slip1>
      <slip2>0</slip2>
    </ode>
    <torsional>
      <coefficient>1</coefficient>
      <patch_radius>0</patch_radius>
      <surface_radius>0</surface_radius>
      <use_patch_radius>1</use_patch_radius>
      <ode>
        <slip>0</slip>
      </ode>
    </torsional>
  </friction>
  <bounce>
    <restitution_coefficient>0</restitution_coefficient>
    <threshold>1e+06</threshold>
  </bounce>
  <contact>
    <collide_without_contact>0</collide_without_contact>
    <collide_without_contact_bitmask>1</collide_without_contact_bitmask>
    <collide_bitmask>1</collide_bitmask>
    <ode>
      <soft_cfm>0</soft_cfm>
      <soft_erp>0.2</soft_erp>
      <kp>1e+10</kp>
      <kd>1</kd>
      <max_vel>0.1</max_vel>
      <min_depth>0.001</min_depth>
    </ode>
    <bullet>
      <split_impulse>1</split_impulse>
      <split_impulse_penetration_threshold>-0.01</split_impulse_penetration_threshold>
      <soft_cfm>0</soft_cfm>
      <soft_erp>0.2</soft_erp>
      <kp>1e+7</kp>
      <kd>1.0</kd>
    </bullet>
  </contact>
</surface>
   </collision>
<material>Gazebo/Purple</material>

</gazebo>
<gazebo reference="p5">
<collision name="p5_collision">
<surface>
  <friction>
    <ode>
      <mu>1.0</mu>
      <mu2>1.0</mu2>
      <fdir1>0 0 0</fdir1>
      <slip1>0</slip1>
      <slip2>0</slip2>
    </ode>
    <torsional>
      <coefficient>1</coefficient>
      <patch_radius>0</patch_radius>
      <surface_radius>0</surface_radius>
      <use_patch_radius>1</use_patch_radius>
      <ode>
        <slip>0</slip>
      </ode>
    </torsional>
  </friction>
  <bounce>
    <restitution_coefficient>0</restitution_coefficient>
    <threshold>1e+06</threshold>
  </bounce>
  <contact>
    <collide_without_contact>0</collide_without_contact>
    <collide_without_contact_bitmask>1</collide_without_contact_bitmask>
    <collide_bitmask>1</collide_bitmask>
    <ode>
      <soft_cfm>0</soft_cfm>
      <soft_erp>0.2</soft_erp>
      <kp>1e+10</kp>
      <kd>1</kd>
      <max_vel>0.1</max_vel>
      <min_depth>0.001</min_depth>
    </ode>
    <bullet>
      <split_impulse>1</split_impulse>
      <split_impulse_penetration_threshold>-0.01</split_impulse_penetration_threshold>
      <soft_cfm>0</soft_cfm>
      <soft_erp>0.2</soft_erp>
      <kp>1e+7</kp>
      <kd>1.0</kd>
    </bullet>
  </contact>
</surface>
   </collision>
    <material>Gazebo/Red</material>

</gazebo>
</robot>
